Workbook
Name EOLSearch: 'Search List'!$C$2:$C$4
Name SearchType: #REF!
Name SearchType: 'Search List'!$A$2:$A$4

Sheet Disclaimer
A1: The National Renewable Energy Laboratory (NREL) is operated for the U.S. Department of Energy (DOE) by Alliance for Sustainable Energy, LLC ("Alliance"). NAATBatt International (NAATBatt) is the trade association for the advanced battery industry in North America.
A3: Access to or use of any data or software made available on this server ("Data") shall impose the following obligations on the user, and use of the Data constitutes user's agreement to these terms. The user is granted the right, without any fee or cost, to use or copy the Data, provided that this entire notice appears in all copies of the Data. Further, the user agrees to credit DOE/NREL/ALLIANCE/NAATBatt in any publication that results from the use of the Data. The names DOE/NREL/ALLIANCE/NAATBatt, however, may not be used in any advertising or publicity to endorse or promote any products or commercial entities unless specific written permission is obtained from DOE/NREL/ ALLIANCE/NAATBatt. The user also understands that DOE/NREL/ALLIANCE/NAATBatt are not obligated to provide the user with any support, consulting, training or assistance of any kind with regard to the use of the Data or to provide the user with any updates, revisions or new versions thereof. DOE, NREL,ALLIANCE, and NAATBatt do not guarantee or endorse any results generated by use of the Data, and user is entirely responsible for the results and any reliance on the results or the Data in general.
A5: USER AGREES TO INDEMNIFY DOE/NREL/ALLIANCE/NAATBATT AND THEIR RESPECTIVE SUBSIDIARIES, AFFILIATES, OFFICERS, AGENTS, AND EMPLOYEES AGAINST ANY CLAIM OR DEMAND, INCLUDING REASONABLE ATTORNEYS' FEES, RELATED TO USER'S USE OF THE DATA. THE DATA ARE PROVIDED BY DOE/NREL/ALLIANCE/NAATBATT "AS IS," AND ANY EXPRESS OR IMPLIED WARRANTIES, INCLUDING BUT NOT LIMITED TO THE IMPLIED WARRANTIES OF MERCHANTABILITY AND FITNESS FOR A PARTICULAR PURPOSE ARE DISCLAIMED. DOE/NREL/ALLIANCE/NAATBATTASSUME NO LEGAL LIABILITY OR RESPONSIBILITY FOR THE ACCURACY, COMPLETENESS, OR USEFULNESS OF THE DATA, OR REPRESENT THAT ITS USE WOULD NOT INFRINGE PRIVATELY OWNED RIGHTS. IN NO EVENT SHALL DOE/NREL/ALLIANCE/NAATBATT BE LIABLE FOR ANY SPECIAL, INDIRECT OR CONSEQUENTIAL DAMAGES OR ANY DAMAGES WHATSOEVER, INCLUDING BUT NOT LIMITED TO CLAIMS ASSOCIATED WITH THE LOSS OF DATA OR PROFITS, THAT MAY RESULT FROM AN ACTION IN CONTRACT, NEGLIGENCE OR OTHER TORTIOUS CLAIM THAT ARISES OUT OF OR IN CONNECTION WITH THE ACCESS, USE OR PERFORMANCE OF THE DATA.
A7: Contributers: Vicky Putsche, Erik Witter, Shriram Santhanagopalan, Maggie Mann, Sara Dunn, Beth Monk, Michael Khalfin and Ahmad A. Pesaran National Renewable Energy Laboratory Version 3 December 7, 2022 NAATBatt International funded this project under two Technical Services Agreements (TSA-21-17854, TSA-21-21593, and TSA-25-33176) with NREL

Sheet User Agreement 
B3: To access and use the Database, you are required to provide certain information and/or answer certain questions and need to accept the terms of the End User License Agreement

Sheet SummaryTable
A1: Current as of: | E1: March 27, 2026
A3: Supply Chain Segment | B3: US | D3: Canada | F3: Other | H3: Total | L3: Canada
B4: Companies | C4: Facilities | D4: Companies | E4: Facilities | F4: Companies | G4: Facilities | H4: Companies | I4: Facilities | L4: US
A5: Raw Material Manufacturing | B5: {=IFERROR(ROWS(_xlfn.UNIQUE(_xlfn._xlws.FILTER('Raw Materials'!$D$2:$D$104,'Raw Materials'!$M$2:$M$104=B3))),0)} -> 42 | C5: {=IFERROR(ROWS(_xlfn.UNIQUE(_xlfn._xlws.FILTER('Raw Materials'!$F$2:$F$104,'Raw Materials'!$M$2:$M$104=B3))),0)} -> 46 | D5: {=IFERROR(ROWS(_xlfn.UNIQUE(_xlfn._xlws.FILTER('Raw Materials'!$D$2:$D$104,'Raw Materials'!$M$2:$M$104=D3))),0)} -> 28 | E5: {=IFERROR(ROWS(_xlfn.UNIQUE(_xlfn._xlws.FILTER('Raw Materials'!$F$2:$F$104,'Raw Materials'!$M$2:$M$104=D3))),0)} -> 41 | F5: {=IFERROR(ROWS(_xlfn.UNIQUE(_xlfn._xlws.FILTER('Raw Materials'!$D$2:$D$104,ISNUMBER(MATCH('Raw Materials'!$M$2:$M$104,$L$3:$L$4,0))=FALSE))),0)} -> 3 | G5: {=IFERROR(ROWS(_xlfn.UNIQUE(_xlfn._xlws.FILTER('Raw Materials'!$F$2:$F$104,ISNUMBER(MATCH('Raw Materials'!$M$2:$M$104,$L$3:$L$4,0))=FALSE))),0)} -> 4 | H5: =IFERROR(ROWS(_xlfn.UNIQUE('Raw Materials'!$D$2:$D$104)),0) -> 73 | I5: =IFERROR(ROWS(_xlfn.UNIQUE('Raw Materials'!$F$2:$F$104)),0) -> 91
A6: Battery Grade Materials Manufacturing | B6: {=IFERROR(ROWS(_xlfn.UNIQUE(_xlfn._xlws.FILTER('Battery Grade Materials'!$D$2:$D$158,'Battery Grade Materials'!$M$2:$M$158=B$3))),0)} -> 84 | C6: {=IFERROR(ROWS(_xlfn.UNIQUE(_xlfn._xlws.FILTER('Battery Grade Materials'!$F$2:$F$158,'Battery Grade Materials'!$M$2:$M$158=B$3))),0)} -> 104 | D6: {=IFERROR(ROWS(_xlfn.UNIQUE(_xlfn._xlws.FILTER('Battery Grade Materials'!$D$2:$D$158,'Battery Grade Materials'!$M$2:$M$158=D$3))),0)} -> 24 | E6: {=IFERROR(ROWS(_xlfn.UNIQUE(_xlfn._xlws.FILTER('Battery Grade Materials'!$F$2:$F$158,'Battery Grade Materials'!$M$2:$M$158=D$3))),0)} -> 27 | F6: {=IFERROR(ROWS(_xlfn.UNIQUE(_xlfn._xlws.FILTER('Battery Grade Materials'!$D$2:$D$158,ISNUMBER(MATCH('Battery Grade Materials'!$M$2:$M$158,$L$3:$L$4,0))=FALSE))),0)} -> 3 | G6: {=IFERROR(ROWS(_xlfn.UNIQUE(_xlfn._xlws.FILTER('Battery Grade Materials'!$F$2:$F$158,ISNUMBER(MATCH('Battery Grade Materials'!$M$2:$M$158,$L$3:$L$4,0))=FALSE))),0)} -> 3 | H6: =IFERROR(ROWS(_xlfn.UNIQUE('Battery Grade Materials'!$D$2:$D$158)),0) -> 111 | I6: =IFERROR(ROWS(_xlfn.UNIQUE('Battery Grade Materials'!$F$2:$F$158)),0) -> 133
A7: Other Battery Components and Materials Manufacturing | B7: {=IFERROR(ROWS(_xlfn.UNIQUE(_xlfn._xlws.FILTER('Other Battery Components & Mat.'!$D$2:$D$106,'Other Battery Components & Mat.'!$M$2:$M$106=B$3))),0)} -> 76 | C7: {=IFERROR(ROWS(_xlfn.UNIQUE(_xlfn._xlws.FILTER('Other Battery Components & Mat.'!$F$2:$F$106,'Other Battery Components & Mat.'!$M$2:$M$106=B$3))),0)} -> 93 | D7: {=IFERROR(ROWS(_xlfn.UNIQUE(_xlfn._xlws.FILTER('Other Battery Components & Mat.'!$D$2:$D$106,'Other Battery Components & Mat.'!$M$2:$M$106=D$3))),0)} -> 6 | E7: {=IFERROR(ROWS(_xlfn.UNIQUE(_xlfn._xlws.FILTER('Other Battery Components & Mat.'!$F$2:$F$106,'Other Battery Components & Mat.'!$M$2:$M$106=D$3))),0)} -> 6 | F7: {=IFERROR(ROWS(_xlfn.UNIQUE(_xlfn._xlws.FILTER('Other Battery Components & Mat.'!$D$2:$D$106,ISNUMBER(MATCH('Other Battery Components & Mat.'!$M$2:$M$106,$L$3:$L$4,0))=FALSE))),0)} -> 1 | G7: {=IFERROR(ROWS(_xlfn.UNIQUE(_xlfn._xlws.FILTER('Other Battery Components & Mat.'!$F$2:$F$106,ISNUMBER(MATCH('Other Battery Components & Mat.'!$M$2:$M$106,$L$3:$L$4,0))=FALSE))),0)} -> 1 | H7: =IFERROR(ROWS(_xlfn.UNIQUE('Battery Grade Materials'!$D$2:$D$95)),0) -> 69 | I7: =IFERROR(ROWS(_xlfn.UNIQUE('Other Battery Components & Mat.'!$F$2:$F$106)),0) -> 99
A8: Electrode and Cells Manufacturing | B8: {=IFERROR(ROWS(_xlfn.UNIQUE(_xlfn._xlws.FILTER('Electrode & Cell Manufacturing'!$D$2:$D$119,'Electrode & Cell Manufacturing'!$M$2:$M$119=B$3))),0)} -> 80 | C8: {=IFERROR(ROWS(_xlfn.UNIQUE(_xlfn._xlws.FILTER('Electrode & Cell Manufacturing'!$F$2:$F$119,'Electrode & Cell Manufacturing'!$M$2:$M$119=B$3))),0)} -> 98 | D8: {=IFERROR(ROWS(_xlfn.UNIQUE(_xlfn._xlws.FILTER('Electrode & Cell Manufacturing'!$D$2:$D$119,'Electrode & Cell Manufacturing'!$M$2:$M$119=D$3))),0)} -> 12 | E8: {=IFERROR(ROWS(_xlfn.UNIQUE(_xlfn._xlws.FILTER('Electrode & Cell Manufacturing'!$F$2:$F$119,'Electrode & Cell Manufacturing'!$M$2:$M$119=D$3))),0)} -> 12 | F8: {=IFERROR(ROWS(_xlfn.UNIQUE(_xlfn._xlws.FILTER('Electrode & Cell Manufacturing'!$D$2:$D$119,ISNUMBER(MATCH('Electrode & Cell Manufacturing'!$M$2:$M$119,$L$3:$L$4,0))=FALSE))),0)} -> 3 | G8: {=IFERROR(ROWS(_xlfn.UNIQUE(_xlfn._xlws.FILTER('Electrode & Cell Manufacturing'!$F$2:$F$119,ISNUMBER(MATCH('Electrode & Cell Manufacturing'!$M$2:$M$119,$L$3:$L$4,0))=FALSE))),0)} -> 3 | H8: =IFERROR(ROWS(_xlfn.UNIQUE('Electrode & Cell Manufacturing'!$D$2:$D$119)),0) -> 89 | I8: =IFERROR(ROWS(_xlfn.UNIQUE('Electrode & Cell Manufacturing'!$F$2:$F$119)),0) -> 113
A9: Modules and Packs Manufacturing | B9: {=IFERROR(ROWS(_xlfn.UNIQUE(_xlfn._xlws.FILTER('Module-Pack Manufacturing'!$D$2:$D$268,'Module-Pack Manufacturing'!$M$2:$M$268=B$3))),0)} -> 183 | C9: {=IFERROR(ROWS(_xlfn.UNIQUE(_xlfn._xlws.FILTER('Module-Pack Manufacturing'!$F$2:$F$268,'Module-Pack Manufacturing'!$M$2:$M$268=B$3))),0)} -> 209 | D9: {=IFERROR(ROWS(_xlfn.UNIQUE(_xlfn._xlws.FILTER('Module-Pack Manufacturing'!$D$2:$D$268,'Module-Pack Manufacturing'!$M$2:$M$268=D$3))),0)} -> 20 | E9: {=IFERROR(ROWS(_xlfn.UNIQUE(_xlfn._xlws.FILTER('Module-Pack Manufacturing'!$F$2:$F$268,'Module-Pack Manufacturing'!$M$2:$M$268=D$3))),0)} -> 23 | F9: {=IFERROR(ROWS(_xlfn.UNIQUE(_xlfn._xlws.FILTER('Module-Pack Manufacturing'!$D$2:$D$268,ISNUMBER(MATCH('Module-Pack Manufacturing'!$M$2:$M$268,$L$3:$L$4,0))=FALSE))),0)} -> 10 | G9: {=IFERROR(ROWS(_xlfn.UNIQUE(_xlfn._xlws.FILTER('Module-Pack Manufacturing'!$F$2:$F$268,ISNUMBER(MATCH('Module-Pack Manufacturing'!$M$2:$M$268,$L$3:$L$4,0))=FALSE))),0)} -> 11 | H9: =IFERROR(ROWS(_xlfn.UNIQUE('Module-Pack Manufacturing'!$D$2:$D$268)),0) -> 202 | I9: =IFERROR(ROWS(_xlfn.UNIQUE('Module-Pack Manufacturing'!$F$2:$F$268)),0) -> 242
A10: Recycling/Repurposing | B10: {=IFERROR(ROWS(_xlfn.UNIQUE(_xlfn._xlws.FILTER('Recycling-Repurposing'!$D$2:$D$133,'Recycling-Repurposing'!$O$2:$O$133=B$3))),0)} -> 85 | C10: {=IFERROR(ROWS(_xlfn.UNIQUE(_xlfn._xlws.FILTER('Recycling-Repurposing'!$F$2:$F$133,'Recycling-Repurposing'!$O$2:$O$133=B$3))),0)} -> 113 | D10: {=IFERROR(ROWS(_xlfn.UNIQUE(_xlfn._xlws.FILTER('Recycling-Repurposing'!$D$2:$D$133,'Recycling-Repurposing'!$O$2:$O$133=D$3))),0)} -> 9 | E10: {=IFERROR(ROWS(_xlfn.UNIQUE(_xlfn._xlws.FILTER('Recycling-Repurposing'!$F$2:$F$133,'Recycling-Repurposing'!$O$2:$O$133=D$3))),0)} -> 11 | F10: {=IFERROR(ROWS(_xlfn.UNIQUE(_xlfn._xlws.FILTER('Recycling-Repurposing'!$D$2:$D$133,ISNUMBER(MATCH('Recycling-Repurposing'!$O$2:$O$133,$L$3:$L$4,0))=FALSE))),0)} -> 0 | G10: {=IFERROR(ROWS(_xlfn.UNIQUE(_xlfn._xlws.FILTER('Recycling-Repurposing'!$F$2:$F$133,ISNUMBER(MATCH('Recycling-Repurposing'!$O$2:$O$133,$L$3:$L$4,0))=FALSE))),0)} -> 0 | H10: =IFERROR(ROWS(_xlfn.UNIQUE('Recycling-Repurposing'!$D$2:$D$133)),0) -> 90 | I10: =IFERROR(ROWS(_xlfn.UNIQUE('Recycling-Repurposing'!$F$2:$F$133)),0) -> 123
A11: Equipment Manufacturing | B11: {=IFERROR(ROWS(_xlfn.UNIQUE(_xlfn._xlws.FILTER(Equipment!$D$5:$D$144,Equipment!$M$5:$M$144=B$3))),0)} -> 99 | C11: {=IFERROR(ROWS(_xlfn.UNIQUE(_xlfn._xlws.FILTER(Equipment!$F$5:$F$144,Equipment!$M$5:$M$144=B$3))),0)} -> 103 | D11: {=IFERROR(ROWS(_xlfn.UNIQUE(_xlfn._xlws.FILTER(Equipment!$D$5:$D$144,Equipment!$M$5:$M$144=D$3))),0)} -> 3 | E11: {=IFERROR(ROWS(_xlfn.UNIQUE(_xlfn._xlws.FILTER(Equipment!$F$5:$F$144,Equipment!$M$5:$M$144=D$3))),0)} -> 3 | F11: {=IFERROR(ROWS(_xlfn.UNIQUE(_xlfn._xlws.FILTER(Equipment!$D$2:$D$145,ISNUMBER(MATCH(Equipment!$M$2:$M$145,$L$3:$L$4,0))=FALSE))),0)} -> 0 | G11: {=IFERROR(ROWS(_xlfn.UNIQUE(_xlfn._xlws.FILTER(Equipment!$F$2:$F$145,ISNUMBER(MATCH(Equipment!$M$2:$M$145,$L$3:$L$4,0))=FALSE))),0)} -> 0 | H11: =IFERROR(ROWS(_xlfn.UNIQUE(Equipment!$D$5:$D$144)),0) -> 102 | I11: =IFERROR(ROWS(_xlfn.UNIQUE(Equipment!$F$5:$F$144)),0) -> 106
A12: R&D | B12: {=IFERROR(ROWS(_xlfn.UNIQUE(_xlfn._xlws.FILTER('R&D'!$D$2:$D$144,'R&D'!$M$2:$M$144=B$3))),0)} -> 117 | C12: {=IFERROR(ROWS(_xlfn.UNIQUE(_xlfn._xlws.FILTER('R&D'!$F$2:$F$144,'R&D'!$M$2:$M$144=B$3))),0)} -> 126 | D12: {=IFERROR(ROWS(_xlfn.UNIQUE(_xlfn._xlws.FILTER('R&D'!$D$2:$D$144,'R&D'!$M$2:$M$144=D$3))),0)} -> 13 | E12: {=IFERROR(ROWS(_xlfn.UNIQUE(_xlfn._xlws.FILTER('R&D'!$F$2:$F$144,'R&D'!$M$2:$M$144=D$3))),0)} -> 13 | F12: {=IFERROR(ROWS(_xlfn.UNIQUE(_xlfn._xlws.FILTER('R&D'!$D$2:$D$144,ISNUMBER(MATCH('R&D'!$M$2:$M$144,$L$3:$L$4,0))=FALSE))),0)} -> 0 | G12: {=IFERROR(ROWS(_xlfn.UNIQUE(_xlfn._xlws.FILTER('R&D'!$F$2:$F$144,ISNUMBER(MATCH('R&D'!$M$2:$M$144,$L$3:$L$4,0))=FALSE))),0)} -> 0 | H12: =IFERROR(ROWS(_xlfn.UNIQUE('R&D'!$D$2:$D$144)),0) -> 129 | I12: =IFERROR(ROWS(_xlfn.UNIQUE('R&D'!$F$2:$F$144)),0) -> 139
A13: Service and Repair | B13: {=IFERROR(ROWS(_xlfn.UNIQUE(_xlfn._xlws.FILTER('Services & Consulting'!$D$2:$D$149,'Services & Consulting'!$L$2:$L$149=B$3))),0)} -> 128 | C13: {=IFERROR(ROWS(_xlfn.UNIQUE(_xlfn._xlws.FILTER('Services & Consulting'!$I$2:$I$149,'Services & Consulting'!$L$2:$L$149=B$3))),0)} -> 128 | D13: {=IFERROR(ROWS(_xlfn.UNIQUE(_xlfn._xlws.FILTER('Services & Consulting'!$D$2:$D$149,'Services & Consulting'!$L$2:$L$149=D$3))),0)} -> 9 | E13: {=IFERROR(ROWS(_xlfn.UNIQUE(_xlfn._xlws.FILTER('Services & Consulting'!$I$2:$I$149,'Services & Consulting'!$L$2:$L$149=D$3))),0)} -> 9 | F13: {=IFERROR(ROWS(_xlfn.UNIQUE(_xlfn._xlws.FILTER('Services & Consulting'!$D$2:$D$149,ISNUMBER(MATCH('Services & Consulting'!$L$2:$L$149,$L$3:$L$4,0))=FALSE))),0)} -> 0 | G13: {=IFERROR(ROWS(_xlfn.UNIQUE(_xlfn._xlws.FILTER('Services & Consulting'!$F$2:$F$149,ISNUMBER(MATCH('Services & Consulting'!$L$2:$L$149,$L$3:$L$4,0))=FALSE))),0)} -> 0 | H13: =IFERROR(ROWS(_xlfn.UNIQUE('Services & Consulting'!$D$2:$D$149)),0) -> 135 | I13: =IFERROR(ROWS(_xlfn.UNIQUE('Services & Consulting'!$I$2:I$149)),0) -> 136
A14: Modeling | B14: {=IFERROR(ROWS(_xlfn.UNIQUE(_xlfn._xlws.FILTER('Modeling & Software'!$D$2:$D$37,'Modeling & Software'!$L$2:$L$37=B$3))),0)} -> 34 | C14: {=IFERROR(ROWS(_xlfn.UNIQUE(_xlfn._xlws.FILTER('Modeling & Software'!$I$2:$I$37,'Modeling & Software'!$L$2:$L$37=B$3))),0)} -> 34 | D14: {=IFERROR(ROWS(_xlfn.UNIQUE(_xlfn._xlws.FILTER('Modeling & Software'!$D$2:$D$37,'Modeling & Software'!$L$2:$L$37=D$3))),0)} -> 2 | E14: {=IFERROR(ROWS(_xlfn.UNIQUE(_xlfn._xlws.FILTER('Modeling & Software'!$F$2:$F$37,'Modeling & Software'!$L$2:$L$37=D$3))),0)} -> 1 | F14: {=IFERROR(ROWS(_xlfn.UNIQUE(_xlfn._xlws.FILTER('Modeling & Software'!$D$2:$D$37,ISNUMBER(MATCH('Modeling & Software'!$L$2:$L$37,$L$3:$L$4,0))=FALSE))),0)} -> 0 | G14: {=IFERROR(ROWS(_xlfn.UNIQUE(_xlfn._xlws.FILTER('Modeling & Software'!$F$2:$F$37,ISNUMBER(MATCH('Modeling & Software'!$L$2:$L$37,$L$3:$L$4,0))=FALSE))),0)} -> 0 | H14: =IFERROR(ROWS(_xlfn.UNIQUE('Modeling & Software'!$D$2:$D$37)),0) -> 35 | I14: =IFERROR(ROWS(_xlfn.UNIQUE('Modeling & Software'!$I$2:$I$37)),0) -> 36
A15: Professional Services | B15: {=IFERROR(ROWS(_xlfn.UNIQUE(_xlfn._xlws.FILTER('Professional Services (NB)'!$D$2:$D$39,'Professional Services (NB)'!$L$2:$L$39=B$3))),0)} -> 35 | C15: {=IFERROR(ROWS(_xlfn.UNIQUE(_xlfn._xlws.FILTER('Professional Services (NB)'!$I$2:$I$39,'Professional Services (NB)'!$L$2:$L$39=B$3))),0)} -> 35 | D15: {=IFERROR(ROWS(_xlfn.UNIQUE(_xlfn._xlws.FILTER('Professional Services (NB)'!$D$2:$D$39,'Professional Services (NB)'!$L$2:$L$39=D$3))),0)} -> 2 | E15: {=IFERROR(ROWS(_xlfn.UNIQUE(_xlfn._xlws.FILTER('Professional Services (NB)'!$I$2:$I$39,'Professional Services (NB)'!$L$2:$L$39=D$3))),0)} -> 2 | F15: {=IFERROR(ROWS(_xlfn.UNIQUE(_xlfn._xlws.FILTER('Professional Services (NB)'!$D$2:$D$39,ISNUMBER(MATCH('Professional Services (NB)'!$L$2:$L$39,$L$3:$L$4,0))=FALSE))),0)} -> 1 | G15: {=IFERROR(ROWS(_xlfn.UNIQUE(_xlfn._xlws.FILTER('Professional Services (NB)'!$F$2:$F$39,ISNUMBER(MATCH('Professional Services (NB)'!$L$2:$L$39,$L$3:$L$4,0))=FALSE))),0)} -> 1 | H15: =IFERROR(ROWS(_xlfn.UNIQUE('Professional Services (NB)'!$D$2:$D$39)),0) -> 38 | I15: =IFERROR(ROWS(_xlfn.UNIQUE('Professional Services (NB)'!$I$2:$I$39)),0) -> 38
A16: Distributors | B16: {=IFERROR(ROWS(_xlfn.UNIQUE(_xlfn._xlws.FILTER(Distributors!$D$2:$D$22,Distributors!$L$2:$L$22=B$3))),0)} -> 8 | C16: {=IFERROR(ROWS(_xlfn.UNIQUE(_xlfn._xlws.FILTER(Distributors!$I$2:$I$22,Distributors!$L$2:$L$22=B$3))),0)} -> 8 | D16: {=IFERROR(ROWS(_xlfn.UNIQUE(_xlfn._xlws.FILTER(Distributors!$D$2:$D$22,Distributors!$L$2:$L$22=D$3))),0)} -> 1 | E16: {=IFERROR(ROWS(_xlfn.UNIQUE(_xlfn._xlws.FILTER(Distributors!$I$2:$I$22,Distributors!$L$2:$L$22=D$3))),0)} -> 1 | F16: {=IFERROR(ROWS(_xlfn.UNIQUE(_xlfn._xlws.FILTER(Distributors!$D$2:$D$22,ISNUMBER(MATCH(Distributors!$L$2:$L$22,$L$3:$L$4,0))=FALSE))),0)} -> 0 | G16: {=IFERROR(ROWS(_xlfn.UNIQUE(_xlfn._xlws.FILTER(Distributors!$F$2:$F$22,ISNUMBER(MATCH(Distributors!$L$2:$L$22,$L$3:$L$4,0))=FALSE))),0)} -> 0 | H16: =IFERROR(ROWS(_xlfn.UNIQUE(Distributors!$D$2:$D$22)),0) -> 9 | I16: =IFERROR(ROWS(_xlfn.UNIQUE(Distributors!$I$2:$I$22)),0) -> 9
A17: Totals | B17: =SUM(B5:B16) -> 971 | C17: =SUM(C5:C16) -> 1097 | D17: =SUM(D5:D16) -> 129 | E17: =SUM(E5:E16) -> 149 | F17: =SUM(F5:F16) -> 21 | G17: =SUM(G5:G16) -> 23 | H17: =SUM(H5:H16) -> 1082 | I17: =SUM(I5:I16) -> 1265

Sheet Glossary
A1: Term | B1: Definition | C1: Source
A2: 4R's | B2: Repair, Remanufacture, Refurbish and/or Repurpose | C2: Battery Pack Design book
A3: Active material | B3: The constituents of a cell that participate in electrochemical charge and/or discharge reactions. This does not inclue separators, current collectors, catalysts or supports | C3: SAE J1715 - Battery Terminology (2021-08)
A4: Anode | B4: The negative battery electrode at which oxidation (a loss of electrons) take place during discharge. | C4: SAE J1715 - Battery Terminology (2021-08)
A5: Battery (RESS Battery) | B5: A general term that inclusively refers to electrochemical cells, modules, packs, and endergy storage systems. | C5: SAE J1715 - Battery Terminology (2021-08)
A6: Battery collection | B6: Gathering of batteries for the purpose of shipment to a treatment facility where treatment facility may include any end of life treatment facility such as a recycler or licensed disposal site; it can also include other processes such as evaluation, remanufacture, and/or repurpose | C6: SAE J2974 - Technical Information Report on Automotive Battery Recycling
A7: Battery grade materials | B7: Materials for batteries that are made at facilities after initial concentration at extraction points
A8: Battery management system (BMS) | B8: An electronic system that monitors, manage,s and may communicate information about performance, safety, and supervisory control ofa battery through battery state estimations and/or fault detections and predictions | C8: SAE J1715 - Battery Terminology (2021-08)
A9: Battery module | B9: Multiple electrochemical cells connected in series or parallel. Batttery modules may or may not include snesors such as voltage and temperature sensors, safety components, and a cooling structure that each module can be controlled and managed independently. | C9: SAE J1715 - Battery Terminology (2021-08)
A10: Battery pack | B10: A battery assembly that consists of one or more modules. A pack may include sensors, interlocks, contactors, battery management controller, safety devices, thermal management, and structural components | C10: SAE J1715 - Battery Terminology (2021-08)
A11: Black mass | B11: The material in an LIB that is released after shredding and screening
A12: BMS | B12: Battery Management System: The BMS is the control system within the battery pack that consists of one or more electronic controllers, which manages the charging and discharging, monitors the temperature and voltage, communicates with the vehicle system, balances the cells, and manages the safety functionality of the battery pack. | C12: Battery Pack Design book
A13: Cathode | B13: The positive battery electrode at which reduction (a gain of electrons) takes place during discharge | C13: SAE J1715 - Battery Terminology (2021-08)
A14: Cell | B14: A basic electrochemical functional unit that at minimum consists of a positive electrode, a negative electrode electrode, and an electrolyte. | C14: SAE J1715 - Battery Terminology (2021-08)
A15: Connector | B15: Conductor of electricity used for carrying current between components in an electric circuit. For example, a connector electrically joins two cells, or a terminal of the battery to an exterior circuit and also to auxiliary devices. | C15: SAE J1715 - Battery Terminology (2021-08)
A16: Collection and Sorting of Feedstock | B16: Recycling processes are enhanced by segregating the feed (spent batteries) into separate fractions based on chemistry. This can greatly reduce the cost of recycling, unwanted emissions, and safety concerns. Presently hand sorting of portable batteries by chemistries is common prior to shipment to recyclers. | C16: SAE J2974 - Technical Information Report on Automotive Battery Recycling
A17: Collection, Disassembly and/or Storage | B17: Facilities that collect vehicles or other products containing batteries and they take the product apart and get the battery and safely store it.
A18: Collection, Sorting Storage, and/or Discharging | B18: Facilities that collect batteries, sort them by battery type or chemistry, safely store them and/or discharge them
A19: Direct recycling | B19: Direct recycling is a hybrid of the processing methods drawing most heavily from physical separation as the goal is to return the feed to the initial application with a minimum of processing. Byproducts are process dependent, and generally dust and particulate emissions may be a concern. Capital cost is expected to be low compared to other processes, and permitting is process specific. This type of process has been applied to the polypropylene cases of lead acid batteries and the metallic cases from Zn/C and alkaline batteries. This type of process has been demonstrated with Ni-MH and Li-ion cells. | C19: SAE J2974 - Technical Information Report on Automotive Battery Recycling
A20: Electrode | B20: The conducting body that contains active materials and through which current enters or leaves a cell. | C20: SAE J1715 - Battery Terminology (2021-08)
A21: Electrolyte | B21: The medium, which can be liquid or solid, that provides ion transport between the positive and negative electrodes of a cell.. Electrolytes may also participate directly in the charge and/or discharge reactions. | C21: SAE J1715 - Battery Terminology (2021-08)
A22: End of Life (EOL) | B22: When a battery fails to meet specified capacity, power, or function in specified use conditions | C22: SAE J1715 - Battery Terminology (2021-08)
A23: Hydrometallurgy | B23: or Hydrometallurgical Processing: Hydrometallurgical processing uses aqueous chemicals, acids, bases or other solvents to leach the material. This is usually followed by species (chemical compound) separation and purification processes. The materials are then precipitated as hydroxides/salts or electrorefined for reuse as metal. Byproducts include: leach residue, waste water that requires further treatment, and sludges from waste water treatment. Hydroxide and salts are often reprocessed in pyrometallurgical facilities to produce metals. Capital cost is typically less than pyrometallurgy depending on target metals recovered, and permitting is reagent specific. This type of process has been applied to lead acid, NiCd, NiMH, and Li-ion. | C23: SAE J2974 - Technical Information Report on Automotive Battery Recycling
A24: Lithium ion battery (LIB) | B24: A rechargeable battery that uses lithium ions as the primary ionic conductor in the electrolyte. | C24: SAE J1715 - Battery Terminology (2021-08)
A25: Module | B25: or Battery module or battery monoblock: Refers to the multiple connections of electrochemical or electrostatic cells. Battery modules amy or may not include sensors such as voltage and temperature sensors, safety components and a cooling structure so that each module can be controlled and managed independently | C25: SAE J2974 - Technical Information Report on Automotive Battery Recycling
A26: Pack | B26: or Battery pack: A battery pack may consist of only one module or multiple modules. The pack includes sensors, interlocks, contactors, battery management controller, safety devices, thermal management, and structural components | C26: SAE J2974 - Technical Information Report on Automotive Battery Recycling
A27: Physical Separation | B27: Physical separation procesess separate target materials based on physical properties, such as size, density, color, conductivity, magnetic susceptibility, and surface chemistry. This process usually involves size reduction, followed by separation and upgrading | C27: SAE J2974 - Technical Information Report on Automotive Battery Recycling
A28: Prismatic cell | B28: Cell with a metallic container with faces that are rectangular. | C28: SAE J1715 - Battery Terminology (2021-08)
A29: Pyrometallurgy | B29: or Pyrometallurgical Processing: Pyrometallurgical processing involves a thermal or high-temperature process in which metals are reduced back to a base metallic state. The oxidation potential of the metals typically determine which metals report to the melt and which report to the slag, this outcome can be somewhat controlled through the atmosphere present in the smelter. Any remaining organic components are burned for energy recovery. Waste and byproducts can include: drosses, slags, soot, and other emissions, as well as high-quality heat. These facilities benefit greatly from economies of scale. Capital cost and permitting burden are high. This type of process has been applied to lead acid, NiCd, NiMH, and Li-ion. | C29: SAE J2974 - Technical Information Report on Automotive Battery Recycling
A30: Rack
A31: Rebuilt | B31: Includes factory rebuilt and remanufactured, and refers to a component (such as a battery) that has been dismantled and reconstructed, as necessary. Its internal and external parts have been cleaned and made rust- and corrosion-free; all impaired, defective, or substantially worn parts have been restored to a sound condition or replaced with new; it has rebuilt (in accordance with the provisions of this paragraph) or unimpaired used parts; all missing parts have been replaced with new, rebuilt, or unimpaired used parts; and such rewinding or machining and other operations have been performed as necessary to put the industry product in sound working condition according to OEM specifications and parameters. | C31: SAE J2974 - Technical Information Report on Automotive Battery Recycling
A32: Recycling | B32: Transformation of end of life products (RESS, batteries, or scrap) into usable products
A33: Refining | B33: Converting a metallic component into another component that is of higher purity using heat, chemicals or other methods
A34: Second life battery | B34: This describes the act of taking a battery system from the end of service life, characterizing the components, and reconfiguring some or all of the components of the battery system for a new application. This may also require new, rebuilt, or unimpaired used parts to be incorporated into the system. Second use requires many of the same commitments as the remanufacture or rebuilding of automotive parts. The difference is the battery may go into a related, but nonautomotive, application. These should be subject to appropriate consensus standards, such as UL 1974 Evaluation for Repurposing Batteries. | C34: SAE J2974 - Technical Information Report on Automotive Battery Recycling
A35: Separator | B35: A cell component placed between the negative and positive electrodes, which electrically isolates or separates the electrodes while allowing ionic conduction to occur. | C35: SAE J1715 - Battery Terminology (2021-08)
A36: Shredding and screening | B36: Physical processing of lithium-ion batteries to produce black mass
A37: Solid electrolyte cell | B37: Cell with an ionically conducting solid as electrolyte. | C37: SAE J1715 - Battery Terminology (2021-08)
A38: Sorted EOL battery | B38: An end of life battery that has been sorted by overall type (e.g., lead-acid vs. lithium-ion) and/or lithium-ion chemistry (e.g., Lithium iron phosphate, Nickel manganese cobalt)
A39: Spodumene | B39: a translucent, typically grayish-white aluminosilicate mineral which is an important source of lithium.
A40: Universal Waste Handler | B40: A facility that processes hazardous waste under universal waste regulations which are: Streamlined hazardous waste management regulation put out by the US at the federal (EPA) and local (state) level, with the goal of promoting the collection and recycling of these materials by easing the regulator burden on the collection and transport, and encouraging the development of programs to reduce the quantity going to municipal solid waste facilities of certain common hazardous wastes. | C40: SAE J2974 - Technical Information Report on Automotive Battery Recycling

Sheet General Search
A1: Directions: | B1: 1. Select the Search Type (Company, Product, State) in the yellow box next to Search Type. 2. Enter the full or partial name of a the selected Search Type in the 2nd yellow box and hit Enter
D3: No. of Records: | G3: =IF(B7<>"",COUNTA(D7:D64004),0) -> 2
A5: Search | D5: Results
A6: Select Search Type (dropdown list): | B6: Company | C6: ID | D6: Status* | E6: NAATBatt Member? | F6: Company | G6: Facility Name | H6: Facility City | I6: Facility State or Province | J6: Facility Country | K6: Product or Service Type | L6: Product or Service | M6: Production Capacity | N6: Units
A7: =IF(B6<>"",B6,"") -> Company | B7: Copper | C7: {=IF($B$6="Company",IF($B$7<>"",_xlfn._xlws.FILTER(Append2[ID],ISNUMBER(SEARCH($B$7,Append2[Company])),"No result"),""),IF($B$6="Product",IF($B$7<>"",_xlfn._xlws.FILTER(Append2[ID],ISNUMBER(SEARCH($B$7,Append2[Product])),"No result"),""), IF($B$6="State",IF($B$7<>"",_xlfn._xlws.FILTER(Append2[ID],ISNUMBER(SEARCH($B$7,Append2[Facility State or Province])),"No result"),""))))} -> 1058 | D7: {=IF($B$6="Company", IF($B$7<>"",_xlfn._xlws.FILTER(Append2[Status],ISNUMBER(SEARCH($B$7,Append2[Company])),"No result"),""),IF($B$6="Product", IF($B$7<>"",_xlfn._xlws.FILTER(Append2[Status],ISNUMBER(SEARCH($B$7,Append2[Product])),"No result"),""), IF($B$6="State", IF($B$7<>"",_xlfn._xlws.FILTER(Append2[Status],ISNUMBER(SEARCH($B$7,Append2[Facility State or Province])),"No result"),""))))} -> Under construction | E7: {=IF($B$6="Company", IF($B$7<>"",_xlfn._xlws.FILTER(Append2[NAATBatt Member],ISNUMBER(SEARCH($B$7,Append2[Company])),"No result"),""),IF($B$6="Product", IF($B$7<>"",_xlfn._xlws.FILTER(Append2[NAATBatt Member],ISNUMBER(SEARCH($B$7,Append2[Product])),"No result"),""), IF($B$6="State", IF($B$7<>"",_xlfn._xlws.FILTER(Append2[NAATBatt Member],ISNUMBER(SEARCH($B$7,Append2[Facility State or Province])),"No result"),""))))} -> No | F7: {=IF($B$6="Company", IF($B$7<>"",_xlfn._xlws.FILTER(Append2[Company],ISNUMBER(SEARCH($B$7,Append2[Company])),"No result"),""),IF($B$6="Product", IF($B$7<>"",_xlfn._xlws.FILTER(Append2[Company],ISNUMBER(SEARCH($B$7,Append2[Product])),"No result"),""),IF($B$6="State", IF($B$7<>"",_xlfn._xlws.FILTER(Append2[Company],ISNUMBER(SEARCH($B$7,Append2[Facility State or Province])),"No result"),""))))} -> NewRange Copper Nickel JV | G7: {=IF($B$6="Company",IF(IF($B$7<>"",_xlfn._xlws.FILTER(Append2[Facility Name],ISNUMBER(SEARCH($B$7,Append2[Company])),"No result"),"")=0,"",IF($B$7<>"",_xlfn._xlws.FILTER(Append2[Facility Name],ISNUMBER(SEARCH($B$7,Append2[Company])),"No result"),"")),IF($B$6="Product",IF(IF($B$7<>"",_xlfn._xlws.FILTER(Append2[Facility Name],ISNUMBER(SEARCH($B$7,Append2[Product])),"No result"),"")=0,"",IF($B$7<>"",_xlfn._xlws.FILTER(Append2[Facility Name],ISNUMBER(SEARCH($B$7,Append2[Product])),"No result"),"")),IF($B$6="State",IF(IF($B$7<>"",_xlfn._xlws.FILTER(Append2[Facility Name],ISNUMBER(SEARCH($B$7,Append2[Facility State or Province])),"No result"),"")=0,"",IF($B$7<>"",_xlfn._xlws.FILTER(Append2[Facility Name],ISNUMBER(SEARCH($B$7,Append2[Facility State or Province])),"No result"),"")))))} -> NewRange Copper Nickel Project | H7: {=IF($B$6="Company",IF($B$7<>"",_xlfn._xlws.FILTER(Append2[Facility City],ISNUMBER(SEARCH($B$7,Append2[Company])),"No result"),""),IF($B$6="Product",IF($B$7<>"",_xlfn._xlws.FILTER(Append2[Facility City],ISNUMBER(SEARCH($B$7,Append2[Product])),"No result"),""),IF($B$6="State",IF($B$7<>"",_xlfn._xlws.FILTER(Append2[Facility City],ISNUMBER(SEARCH($B$7,Append2[Facility State or Province])),"No result"),""))))} -> Hoyt Lakes | I7: {=IF($B$6="Company",IF($B$7<>"",_xlfn._xlws.FILTER(Append2[Facility State or Province],ISNUMBER(SEARCH($B$7,Append2[Company])),"No result"),""),IF($B$6="Product",IF($B$7<>"",_xlfn._xlws.FILTER(Append2[Facility State or Province],ISNUMBER(SEARCH($B$7,Append2[Product])),"No result"),""),IF($B$6="State",IF($B$7<>"",_xlfn._xlws.FILTER(Append2[Facility State or Province],ISNUMBER(SEARCH($B$7,Append2[Facility State or Province])),"No result"),""))))} -> MN | J7: {=IF($B$6="Company",IF($B$7<>"",_xlfn._xlws.FILTER(Append2[Facility Country],ISNUMBER(SEARCH($B$7,Append2[Company])),"No result"),""),IF($B$6="Product",IF($B$7<>"",_xlfn._xlws.FILTER(Append2[Facility Country],ISNUMBER(SEARCH($B$7,Append2[Product])),"No result"),""),IF($B$6="State",IF($B$7<>"",_xlfn._xlws.FILTER(Append2[Facility Country],ISNUMBER(SEARCH($B$7,Append2[Facility State or Province])),"No result"),""))))} -> US | K7: {=IF($B$6="Company",IF($B$7<>"",_xlfn._xlws.FILTER(Append2[Product/Facility Type],ISNUMBER(SEARCH($B$7,Append2[Company])),"No result"),""),IF($B$6="Product",IF($B$7<>"",_xlfn._xlws.FILTER(Append2[Product/Facility Type],ISNUMBER(SEARCH($B$7,Append2[Product/Facility Type])),"No result"),""),IF($B$6="State",IF($B$7<>"",_xlfn._xlws.FILTER(Append2[Product/Facility Type],ISNUMBER(SEARCH($B$7,Append2[Facility State or Province])),"No result"),""))))} -> Cathode raw materials | L7: {=IF($B$6="Company",IF($B$7<>"",_xlfn._xlws.FILTER(Append2[Product],ISNUMBER(SEARCH($B$7,Append2[Company])),"No result"),""),IF($B$6="Product",IF($B$7<>"",_xlfn._xlws.FILTER(Append2[Product],ISNUMBER(SEARCH($B$7,Append2[Product])),"No result"),""),IF($B$6="State",IF($B$7<>"",_xlfn._xlws.FILTER(Append2[Product],ISNUMBER(SEARCH($B$7,Append2[Facility State or Province])),"No result"),""))))} -> Nickel concentrates | M7: {=IF($B$6="Company",IF($B$7<>"",_xlfn._xlws.FILTER(Append2[Production Capacity],ISNUMBER(SEARCH($B$7,Append2[Company])),"No result"),""),IF($B$6="Product",IF($B$7<>"",_xlfn._xlws.FILTER(Append2[Production Capacity],ISNUMBER(SEARCH($B$7,Append2[Product])),"No result"),""),IF($B$6="State",IF($B$7<>"",_xlfn._xlws.FILTER(Append2[Production Capacity],ISNUMBER(SEARCH($B$7,Append2[Facility State or Province])),"No result"),""))))} -> 0 | N7: {=IF($B$6="Company",IF($B$7<>"",_xlfn._xlws.FILTER(Append2[Production Units],ISNUMBER(SEARCH($B$7,Append2[Company])),"No result"),""),IF($B$6="Product",IF($B$7<>"",_xlfn._xlws.FILTER(Append2[Production Units],ISNUMBER(SEARCH($B$7,Append2[Product])),"No result"),""),IF($B$6="State",IF($B$7<>"",_xlfn._xlws.FILTER(Append2[Production Units],ISNUMBER(SEARCH($B$7,Append2[Facility State or Province])),"No result"),""))))} -> 0
A8: Note: | B8: If a company is in the Recycling/ Repurposing sector (e.g. Second Use), use the Recycling_Repurposing Search sheet instead | C8: 2037 | D8: Commercial | E8: No | F8: Boleo Copper Project | G8: Boleo Copper/ Cobalt Mine | H8: Santa Rosalia | I8: Baja California Sur | J8: Mexico | K8: Cathode Battery Grade Materials | L8: Cobalt oxide | M8: 1700 | N8: MT
B10: *Status
B11: C - Commercial
B12: P - Planned
B13: PC-SU - Pre-commercial/ startup
B14: UC - Under construction

Sheet Recycling_Repurpoing  Search
A1: Directions: | B1: 1. Select the Search Type (Company, Facility Type, State) in the green box next to Search Type. 2. Enter the full or partial name of a the selected Search Type in the 2nd green box and hit Enter
D3: No. of Records: | G3: =IF(B6<>"",COUNTA(D6:D64002),0) -> 4
A4: Search | D4: Results
A5: Select Search Type (dropdown list): | B5: Company | C5: ID | D5: Status* | E5: NAATBatt Member? | F5: Company | G5: Facility Name | H5: Facility City | I5: Facility State or Province | J5: Facility Country | K5: Facility Type | L5: Feedstock | M5: Product | N5: Production Capacity | O5: Units
A6: =IF(B5<>"",B5,"") -> Company | B6: recycler | C6: {=IF($B$5="Company",IF($B$6<>"",_xlfn._xlws.FILTER(EOL_Tbl[ID],ISNUMBER(SEARCH($B$6,EOL_Tbl[Company])),"No result"),""),IF($B$5="Facility Type",IF($B$6<>"",_xlfn._xlws.FILTER(EOL_Tbl[ID],ISNUMBER(SEARCH($B$6,EOL_Tbl[Product/Facility Type])),"No result"),""),IF($B$5="State",IF($B$6<>"",_xlfn._xlws.FILTER(EOL_Tbl[ID],ISNUMBER(SEARCH($B$6,EOL_Tbl[Facility State or Province])),"No result"),""))))} -> 6023 | D6: {=IF($B$5="Company",IF($B$6<>"",_xlfn._xlws.FILTER(EOL_Tbl[Status],ISNUMBER(SEARCH($B$6,EOL_Tbl[Company])),"No result"),""),IF($B$5="Facility Type",IF($B$6<>"",_xlfn._xlws.FILTER(EOL_Tbl[Status],ISNUMBER(SEARCH($B$6,EOL_Tbl[Product/Facility Type])),"No result"),""),IF($B$5="State",IF($B$6<>"",_xlfn._xlws.FILTER(EOL_Tbl[Status],ISNUMBER(SEARCH($B$6,EOL_Tbl[Facility State or Province])),"No result"),""))))} -> Commercial | E6: {=IF($B$5="Company",IF($B$6<>"",_xlfn._xlws.FILTER(EOL_Tbl[NAATBatt Member],ISNUMBER(SEARCH($B$6,EOL_Tbl[Company])),"No result"),""),IF($B$5="Facility Type",IF($B$6<>"",_xlfn._xlws.FILTER(EOL_Tbl[NAATBatt Member],ISNUMBER(SEARCH($B$6,EOL_Tbl[Product/Facility Type])),"No result"),""),IF($B$5="State",IF($B$6<>"",_xlfn._xlws.FILTER(EOL_Tbl[NAATBatt Member],ISNUMBER(SEARCH($B$6,EOL_Tbl[Facility State or Province])),"No result"),""))))} -> No | F6: {=IF($B$5="Company",IF($B$6<>"",_xlfn._xlws.FILTER(EOL_Tbl[Company],ISNUMBER(SEARCH($B$6,EOL_Tbl[Company])),"No result"),""),IF($B$5="Facility Type",IF($B$6<>"",_xlfn._xlws.FILTER(EOL_Tbl[Company],ISNUMBER(SEARCH($B$6,EOL_Tbl[Product/Facility Type])),"No result"),""),IF($B$5="State",IF($B$6<>"",_xlfn._xlws.FILTER(EOL_Tbl[Company],ISNUMBER(SEARCH($B$6,EOL_Tbl[Facility State or Province])),"No result"),""))))} -> Battery Recyclers of America | G6: {=IF($B$5="Company",IF($B$6<>"",_xlfn._xlws.FILTER(EOL_Tbl[Facility Name],ISNUMBER(SEARCH($B$6,EOL_Tbl[Company])),"No result"),""),IF($B$5="Facility Type",IF($B$6<>"",_xlfn._xlws.FILTER(EOL_Tbl[Facility Name],ISNUMBER(SEARCH($B$6,EOL_Tbl[Product/Facility Type])),"No result"),""),IF($B$5="State",IF($B$6<>"",_xlfn._xlws.FILTER(EOL_Tbl[Facility Name],ISNUMBER(SEARCH($B$6,EOL_Tbl[Facility State or Province])),"No result"),""))))} -> Battery Recyclers of America | H6: {=IF($B$5="Company",IF($B$6<>"",_xlfn._xlws.FILTER(EOL_Tbl[Facility City],ISNUMBER(SEARCH($B$6,EOL_Tbl[Company])),"No result"),""),IF($B$5="Facility Type",IF($B$6<>"",_xlfn._xlws.FILTER(EOL_Tbl[Facility City],ISNUMBER(SEARCH($B$6,EOL_Tbl[Product/Facility Type])),"No result"),""),IF($B$5="State",IF($B$6<>"",_xlfn._xlws.FILTER(EOL_Tbl[Facility City],ISNUMBER(SEARCH($B$6,EOL_Tbl[Facility State or Province])),"No result"),""))))} -> Dallas | I6: {=IF($B$5="Company",IF($B$6<>"",_xlfn._xlws.FILTER(EOL_Tbl[Facility State or Province],ISNUMBER(SEARCH($B$6,EOL_Tbl[Company])),"No result"),""),IF($B$5="Facility Type",IF($B$6<>"",_xlfn._xlws.FILTER(EOL_Tbl[Facility State or Province],ISNUMBER(SEARCH($B$6,EOL_Tbl[Product/Facility Type])),"No result"),""),IF($B$5="State",IF($B$6<>"",_xlfn._xlws.FILTER(EOL_Tbl[Facility State or Province],ISNUMBER(SEARCH($B$6,EOL_Tbl[Facility State or Province])),"No result"),""))))} -> TX | J6: {=IF($B$5="Company",IF($B$6<>"",_xlfn._xlws.FILTER(EOL_Tbl[Facility Country],ISNUMBER(SEARCH($B$6,EOL_Tbl[Company])),"No result"),""),IF($B$5="Facility Type",IF($B$6<>"",_xlfn._xlws.FILTER(EOL_Tbl[Facility Country],ISNUMBER(SEARCH($B$6,EOL_Tbl[Product/Facility Type])),"No result"),""),IF($B$5="State",IF($B$6<>"",_xlfn._xlws.FILTER(EOL_Tbl[Facility Country],ISNUMBER(SEARCH($B$6,EOL_Tbl[Facility State or Province])),"No result"),""))))} -> US | K6: {=IF($B$5="Company",IF($B$6<>"",_xlfn._xlws.FILTER(EOL_Tbl[Product/Facility Type],ISNUMBER(SEARCH($B$6,EOL_Tbl[Company])),"No result"),""),IF($B$5="Facility Type",IF($B$6<>"",_xlfn._xlws.FILTER(EOL_Tbl[Product/Facility Type],ISNUMBER(SEARCH($B$6,EOL_Tbl[Product/Facility Type])),"No result"),""),IF($B$5="State",IF($B$6<>"",_xlfn._xlws.FILTER(EOL_Tbl[Product/Facility Type],ISNUMBER(SEARCH($B$6,EOL_Tbl[Facility State or Province])),"No result"),""))))} -> Collection, Disassembling and/ or Storage (Universal Waste Handlers) | L6: {=IF($B$5="Company",IF($B$6<>"",_xlfn._xlws.FILTER(EOL_Tbl[Feedstock],ISNUMBER(SEARCH($B$6,EOL_Tbl[Company])),"No result"),""),IF($B$5="Facility Type",IF($B$6<>"",_xlfn._xlws.FILTER(EOL_Tbl[Feedstock],ISNUMBER(SEARCH($B$6,EOL_Tbl[Product/Facility Type])),"No result"),""),IF($B$5="State",IF($B$6<>"",_xlfn._xlws.FILTER(EOL_Tbl[Feedstock],ISNUMBER(SEARCH($B$6,EOL_Tbl[Facility State or Province])),"No result"),""))))} -> End-of-life Battery | M6: {=IF($B$5="Company",IF($B$6<>"",_xlfn._xlws.FILTER(EOL_Tbl[Product],ISNUMBER(SEARCH($B$6,EOL_Tbl[Company])),"No result"),""),IF($B$5="Facility Type",IF($B$6<>"",_xlfn._xlws.FILTER(EOL_Tbl[Product],ISNUMBER(SEARCH($B$6,EOL_Tbl[Product/Facility Type])),"No result"),""),IF($B$5="State",IF($B$6<>"",_xlfn._xlws.FILTER(EOL_Tbl[Product],ISNUMBER(SEARCH($B$6,EOL_Tbl[Facility State or Province])),"No result"),""))))} -> Sorted End-of-life Battery | N6: {=IF($B$5="Company",IF($B$6<>"",_xlfn._xlws.FILTER(EOL_Tbl[Capacity],ISNUMBER(SEARCH($B$6,EOL_Tbl[Company])),"No result"),""),IF($B$5="Facility Type",IF($B$6<>"",_xlfn._xlws.FILTER(EOL_Tbl[Capacity],ISNUMBER(SEARCH($B$6,EOL_Tbl[Product/Facility Type])),"No result"),""),IF($B$5="State",IF($B$6<>"",_xlfn._xlws.FILTER(EOL_Tbl[Capacity],ISNUMBER(SEARCH($B$6,EOL_Tbl[Facility State or Province])),"No result"),""))))} -> 0 | O6: {=IF($B$5="Company",IF($B$6<>"",_xlfn._xlws.FILTER(EOL_Tbl[Capacity Units],ISNUMBER(SEARCH($B$6,EOL_Tbl[Company])),"No result"),""),IF($B$5="Facility Type",IF($B$6<>"",_xlfn._xlws.FILTER(EOL_Tbl[Capacity Units],ISNUMBER(SEARCH($B$6,EOL_Tbl[Product/Facility Type])),"No result"),""),IF($B$5="State",IF($B$6<>"",_xlfn._xlws.FILTER(EOL_Tbl[Capacity Units],ISNUMBER(SEARCH($B$6,EOL_Tbl[Facility State or Province])),"No result"),""))))} -> 0
A7: Note: | C7: 6025 | D7: Commercial | E7: No | F7: Blue Star Recyclers | G7: Denver | H7: Denver | I7: CO | J7: US | K7: Collection, Disassembling and/ or Storage (Universal Waste Handlers) | L7: Consumer Electronics | M7: Sorted End-of-life Battery | N7: 10500 | O7: tons electronic waste/yr
C8: 6067 | D8: Commercial | E8: Yes | F8: Interco - A Metaltronics Recycler | G8: Interco | H8: Madison | I8: IL | J8: US | K8: Shredding/ Black mass production | L8: End-of-life Battery | M8: Black Mass | N8: 24000 | O8: MT/yr
B9: *Status | C9: 6125 | D9: Pre-commercial/ startup | E9: Yes | F9: United Battery Recyclers Int | G9: United Battery Recyclers Int | H9: Fenton | I9: MI | J9: US | K9: Shredding/ Black mass production | L9: End-of-life Battery | M9: Black Mass
B10: C - Commercial
B11: P - Planned
B12: PC-SU - Pre-commercial/ startup
B13: UC - Under construction

Sheet Append2
A1: ID | B1: Status | C1: Supply Chain Segment | D1: Company | E1: NAATBatt Member | F1: Facility Name | G1: Product/Facility Type | H1: Product | I1: Company Website | J1: Facility Address | K1: Facility City | L1: Facility State or Province | M1: Facility Country | N1: Facility Zip | O1: Facility Phone | P1: Latitude | Q1: Longitude | R1: Facility Workforce | S1: Production Capacity | T1: Production Units | U1: HQ Company | V1: HQ Company Website | W1: HQ City | X1: HQ State or Province | Y1: HQ Country | Z1: QC | AA1: QC Date | AB1: Sources | AC1: Brief Company Profile | AD1: Summary Word Count | AE1: Notes | AF1: Contact | AG1: Contact email | AH1: Contact Phone | AI1: Long Description | AJ1: Sources2 | AK1: Contact Email2 | AL1: Column1 | AM1: Supply Chain Segment | AN1: Long description3
A2: 1001 | B2: Pre-commercial/ startup | C2: Upstream | D2: Aether | E2: Yes | F2: Aether | G2: Cathode raw materials | H2: Lithium | I2: https://www.aetherbio.com/ | J2: 1455 Adams Dr | K2: Menlo Park | L2: CA | M2: US | N2: 94025 | O2: 415-316-3591 | P2: 37.478008 | Q2: -122.14252 | R2: 40 | U2: Aether | V2: https://www.aetherbio.com/ | W2: Aether | X2: CA | Y2: US | Z2: VP | AA2: 45339 | AC2: Aether engineers enzymes to make novel products. It recently developed a cheaper, faster and more sustainable direct lithium extraction technology using robotics, machine learning, and synthetic biology. | AD2: 27
A3: 1002 | B3: Pre-commercial/ startup | C3: Upstream | D3: Alaska Energy Metals Corp | E3: No | F3: Nikolai Project | G3: Mining & metals | H3: Nickel, copper, cobalt, chromium, iron, platinum, palladium, gold | I3: https://alaskaenergymetals.com/ | K3: Delta Junction | L3: AK | M3: US | O3: 907-677-7479 | P3: 63.5236 | Q3: -145.8222 | U3: Alaska Energy Metals Corp | V3: https://alaskaenergymetals.com/ | W3: Vancouver | X3: BC | Y3: US | Z3: MK | AA3: 45872 | AB3: https://www.morningstar.com/news/accesswire/1052272msn/alaska-energy-metals-enters-memorandum-of-understanding-with-american-electric-vehicle-manufacturer-lucid-and-other-mining-and-processing-companies | AC3: Alaska Energy Metals is a mineral exploration company focused on developing its large-scale Nikolai Project in Alaska to become a domestic source of strategic and critical metals for North America. | AD3: 30 | AE3: The company is actively exploring the site to define the resources they will focus on. They also have an office in Anchorage, AK.
A4: 1003 | B4: Commercial | C4: Upstream | D4: Albemarle Corporation | E4: Yes | F4: Albemarle Corporation, Silver Peak NV | G4: Cathode raw materials | H4: Lithium carbonate - crude | I4: https://www.albemarle.com/ | J4: HWY 265 | K4: Silver Peak | L4: NV | M4: US | N4: 89047 | O4: 775-937-2222 | P4: 37.740208 | Q4: -117.79232 | R4: 75 | S4: 5000 | T4: MT contained Li/yr | U4: Albermarle | V4: https://www.albermarle.com/ | W4: Charlotte | X4: NC | Y4: US | Z4: VP MK | AB4: Capacity from BNEF: Interactive Datasets / Metals/ Mine Assets Map/ Lithium; albermarle.com; Questionnaire; https://www.leg.state.nv.us/App/InterimCommittee/REL/Document/16038#:~:text=We%20have%2065%20employees%20and,is%20about%20%2494%2C000%20a%20year.&text=We%20thank%20you%20for%20the%20opportunity%20to%20speak%20to%20you%20today.&text=Global%20specialty%20chemicals%20company%20with,lithium%2C%20bromine%20and%20refining%20catalysts; https://www.mining.com/albemarle-to-double-lithium-production-in-nevada/ | AC4: Albemarle is a chemical company that provides lithium carbonate and lithium hydroxide as cathode precursors, lithium bis-(oxalato)borate for liquid electrolytes, and lithium sulfide as a solid electrolyte. | AD4: 27 | AE4: Expects to double production; Expansion possible after completing federal permitting in Feb 2026
A5: 1004 | B5: Commercial | C5: Upstream | D5: Albemarle Corporation | E5: Yes | F5: Albemarle - Kings Mountain, NC | G5: Cathode raw materials | H5: Lithium hydroxide - crude | I5: https://www.albemarle.com/ | J5: 348 Holiday Inn Drive | K5: Kings Mountain | L5: NC | M5: US | N5: 28086 | O5: 704-739-2501 | P5: 35.220466 | Q5: -81.341653 | R5: 170 | S5: 5500 | T5: MT contained Li/yr | U5: Albermarle | V5: https://www.albemarle.com/ | W5: Charlotte | X5: NC | Y5: US | Z5: VP | AA5: 44417 | AB5: albermarle.com; BNEF: US Supply Chain Security; Questionnaire; https://www.shelbystar.com/story/news/2022/03/25/kings-mountain-corporation-restart-lithium-mining/7130284001/ | AC5: Albemarle is a chemical company that provides lithium carbonate and lithium hydroxide as cathode precursors, lithium bis-(oxalato)borate for liquid electrolytes, and lithium sulfide as a solid electrolyte. | AD5: 27 | AE5: Pilot facility that mines spodumene, produces battery grade Li-hydroxide, Li-carbonate, and more
A6: 1005 | B6: Planned | C6: Upstream | D6: American Lithium | E6: No | F6: Tonopah Lithium Claims (TLC) Project | G6: Direct lithium extraction | H6: Lithium Sedimentary | I6: https://americanlithiumcorp.com/tlc-lithium-project/ | K6: Tonopah | L6: NV | M6: US | N6: 89049 | O6: 604-428-6126 | P6: 38.125 | Q6: -117.285 | S6: 38000 | T6: MT contained Li/yr | U6: American Lithium Corp | V6: https://americanlithiumcorp.com/ | W6: Vancouver | X6: BC | Y6: Canada | Z6: MK | AA6: 46064 | AB6: https://americanlithiumcorp.com/wp-content/uploads/2026/01/American-Lithium-Investor-Presentation-2026-01-05.pdf; https://americanlithiumcorp.com/tlc-lithium-project/ | AC6: American Lithium develops large-scale lithium projects in Nevada and Peru, utilizing sustainable mining and extraction methods to supply battery-grade lithium for the EV and energy storage sectors. | AD6: 27 | AE6: SOP 2028
A7: 1006 | B7: Pre-commercial/ startup | C7: Upstream | D7: Anson Resources | E7: No | F7: Paradox Lithium Project | G7: Direct lithium extraction | H7: Lithium Carbonate | I7: https://www.ansonresources.com/ | K7: Moab | L7: UT | M7: US | N7: 84532 | O7: 702 759 0182 | P7: 38.572695 | Q7: -109.54767 | R7: 5 | S7: 13000 | T7: MT contained Li/yr | U7: Anson Resources | V7: https://www.ansonresources.com/ | W7: West Perth | X7: Western Australia | Y7: Australia | Z7: MK | AA7: 45649 | AB7: https://www.ansonresources.com/paradox_lithium_project/; https://www.businessnewsasia.com/2024050152386375-anson-resources-signs-lithium-supply-agreement-with-lg-energy-solution/; https://mining.com.au/anson-resources-completes-dfs-at-paradox-lithium-project-us/ | AC7: Anson Resources is an ASX-listed mineral resources company developing the Paradox Lithium Project in Utah, aiming to become a significant supplier of lithium carbonate for the global EV battery market. | AD7: 30 | AE7: Anson Resources has signed a binding offtake agreement with LG Energy Solution to supply battery-grade lithium carbonate from the Paradox Project.
A8: 1007 | B8: Planned | C8: Upstream | D8: Anson Resources | E8: No | F8: Green River DLE Demonstration Plant | G8: Direct lithium extraction | H8: Lithium Brine | I8: https://www.ansonresources.com/ | J8: Green River Industrial Site | K8: Green River | L8: UT | M8: US | N8: 84525 | P8: 38.9955 | Q8: 110.1597 | R8: 80 | U8: Posco Holdings; Anson Resources | V8: http://www.posco-inc.com/poscoinc/v3/eng/index.jsp; https://www.ansonresources.com/ | W8: Seoul; West Perth | X8: NA; Western Australia | Y8: South Korea; Australia | Z8: MK | AA8: 46064 | AB8: https://investingnews.com/anson-resources-update-on-cooperation-between-anson-and-posco-holdings-for-dle-green-river-demonstration-plant/; https://www.accessnewswire.com/newsroom/en/metals-and-mining/anson-resources-update-on-cooperation-between-anson-and-posco-holdings-for-dle-gr-1118215 | AC8: POSCO Holdings is a global leader in steel and battery materials; it is advancing proprietary DLE technology and securing North American lithium resources to support a resilient EV supply chain. | AD8: 30
A9: 1008 | B9: Planned | C9: Upstream | D9: Arcadium Lithium | E9: No | F9: https://jamesbay.allkem.co/en/ | G9: Cathode raw materials | H9: Spodumene concentrates | I9: https://arcadiumlithium.com/ | J9: northern Québec, approximately 130 km east of James Bay and the Cree Nation of Eastmain community. | L9: QC | M9: Canada | P9: 53.536891 | Q9: -80.545652 | R9: 250 (Planned) | S9: 8100 | T9: MT contained Li/yr | U9: Arcadium Lithium | V9: https://arcadiumlithium.com/ | W9: Shannon | Y9: Ireland | Z9: VP | AA9: 44930 | AB9: https://www.mining-technology.com/news/canada-nod-galaxy-james-lithium/?cf-view; https://www.allkem.co/contact; https://iaac-aeic.gc.ca/050/evaluations/proj/80141 | AC9: Arcadium Lithium (2024 merger of Alkem and Livent) delivers sustainable lithium products globally, from resources in Argentina and Australia and conversion assets in the U.S., Asia, and the U.K. | AD9: 29 | AE9: Alkem and Livent merged in 2024
A10: 1009 | B10: Pre-commercial/ startup | C10: Upstream | D10: BHE Renewables | E10: No | F10: CalEnergy Operations | G10: Direct lithium extraction | H10: Lithium | I10: https://www.bherenewables.com/ | J10: 7030 Gentry Rd | K10: Calipatria | L10: CA | M10: US | N10: 92233 | P10: 33.335889 | Q10: -115.65919 | R10: 240 | S10: 90000 | T10: MT contained Li/yr | U10: BHE Renewables | V10: https://www.bherenewables.com/ | W10: Des Moines | X10: IA | Y10: US | Z10: MK | AA10: 45649 | AB10: https://www.linkedin.com/company/forcustomersforcommunities/about/; https://www.bherenewables.com/projects/geothermal; https://www.bherenewables.com/news/customers/occidental-and-bhe-renewables-form-joint-venture--to-commercialize-terralithium-extraction-technology | AC10: BHE Renewables owns and operates renewable energy projects, including geothermal facilities, and is collaborating with Occidental to develop lithium extraction technologies. | AD10: 21 | AF10: Dan Winters | AG10: dan.winters@bherenewables.com | AH10: 515-240-8395 | AI10: BHE Renewables, in partnership with Occidental and TerraLithium, is developing lithium extraction capabilities using patented Direct Lithium Extraction (DLE) technology at its Imperial Valley geothermal plants. This collaboration aims to produce high-purity lithium hydroxide and lithium carbonate to meet the rising demand for battery materials. TerraLithium's environmentally responsible approach processes brine extracted during geothermal energy production, supporting clean energy goals.
A11: 1010 | B11: Planned | C11: Upstream | D11: Canada Nickel Company | E11: No | F11: Crawford | G11: Cathode raw materials | H11: Nickel concentrates | I11: https://canadanickel.com/ | K11: Timmins | L11: ON | M11: Canada | P11: 48.476151 | Q11: -81.33084 | R11: 34 | S11: 48000 | T11: MT Ni/yr | U11: Canadian Nickel | V11: https://canadanickel.com/ | W11: Toronto | X11: ON | Y11: Canada | Z11: VP | AA11: 45463 | AB11: https://canadanickel.com/ https://northernontario.ctvnews.ca/study-shows-massive-nickel-deposit-in-northern-ont-even-more-profitable-than-expected-1.6600455; https://canadanickel.com/wp-content/uploads/2024/05/CNC_InvestorDeck_May2024_VF.pdf | AC11: Canada Nickel is advancing high-quality, high-potential nickel projects to deliver the metals to power the EV revolution and feed the stainless steel market. | AD11: 23 | AE11: Average annual production is expected to be438,000 tons of nickel over the 27-year peak production lifespan. The project will also produce significant amounts of cobalt, palladium, platinum, iron and chromite. Along with our flagship Crawford Nickel Project, Canada Nickel has acquired multiple properties in the region. Unlocking the potential for a Timmins Zero Carbon Nickel District with the consolidation of twenty plus nickel targets.
A12: 1011 | B12: Planned | C12: Upstream | D12: Canadian Royalties | E12: No | F12: Nunavik Nickel Project | G12: Cathode raw materials | H12: Nickel | I12: https://www.canadianroyalties.com/ | J12: Raglan Rd | K12: Donaldson | L12: QC | M12: Canada | N12: J0M 1K0 | P12: 61.561675 | Q12: -73.42748 | R12: 380 (Planned) | U12: Canadian Royalties | V12: https://www.canadianroyalties.com/ | W12: Montreal | X12: QC | Y12: Canada | Z12: MK | AA12: 45649 | AB12: https://www.canadianroyalties.com/articles/20230418200434/towards-phase-the-nunavik-nickel-project.html; https://www.mining-technology.com/marketdata/five-largest-nickel-mines-canada-2020/ | AC12: Canadian Royalties operates one of Canada’s largest nickel mining projects, supporting the growing demand for battery materials in the electric vehicle market. | AD12: 22
A13: 1012 | B13: Planned | C13: Upstream | D13: Century Lithium | E13: No | F13: Clayton Valley Lithium Project | G13: Cathode raw materials | H13: Lithium carbonate - crude | I13: https://www.centurylithium.com/ | K13: Clayton Valley | L13: NV | M13: US | N13: 89047 | P13: 37.752532 | Q13: -117.59062 | R13: 183 (Planned) | S13: 27400 | T13: MT/yr LCE | U13: Century Lithium Corp. | V13: https://www.centurylithium.com/ | W13: Vancouver | X13: BC | Y13: Canada | Z13: VP MK | AB13: Jay DB; www.centurylithium.com/_resources/technical-reports/cyp_pfs_amended_march_15th-2021.pdf?v=0.651?v=0.909?v=0.389; https://www.sudburyminingsolutions.com/top-stories/having-nickel-in-timmins-extremely-attractive-says-ceo-6601589; https://www.centurylithium.com/_resources/technical-reports/cyp_pfs_amended_march_15th-2021.pdf?v=0.483; consulting with Avicenne | AC13: Century Lithium is a Canadian-based advanced stage lithium exploration company advancing towards its goal of producing high-purity lithium carbonate for the electric vehicle and battery storage market. | AD13: 27 | AE13: SOP 203x
A14: 1013 | B14: Under Construction | C14: Upstream | D14: Chevron USA | E14: No | F14: East Texas Southwest Arkansas Lithium Project | G14: Lithium | H14: Direct Lithium Extraction (DLE) | I14: https://www.chevron.com | J14: ~125,000 net acres in the Smackover Formation | L14: TX & AK | M14: US | O14: 925-842-1000 | P14: 33.021943 | Q14: -94.060902 | U14: Chevron Corp | V14: https://www.chevron.com | W14: Houston | X14: TX | Y14: US | Z14: MK | AA14: 45867 | AB14: https://www.businesswire.com/news/home/20250617717350/en/Chevron-Enters-Domestic-Lithium-Sector-to-Support-U.S.-Energy-Security, https://www.ogj.com/energy-transition/article/55297744/chevron-enters-us-lithium-sector-with-leasehold-acquisitions | AC14: Chevron is a multinational energy corporation that has recently entered the domestic lithium sector to support U.S. energy security and expand its new energies business. | AD14: 25
A15: 1014 | B15: Pre-commercial/ startup | C15: Upstream | D15: Cobalt 27 Capital Corporation | E15: No | F15: Cobalt 27 Capital Corporation | G15: Cathode raw materials | H15: Cobalt ore | I15: https://nickel28.com/ | J15: 700 West Georgia Street | K15: Vancouver | L15: BC | M15: Canada | N15: BC V7Y 1B3 | O15: 414-560-9070 | P15: 49.282945 | Q15: -123.11916 | R15: 4 | U15: Nickel 28 | V15: https://nickel28.com/ | W15: Toronto | X15: ON | Y15: Canada | Z15: VP | AA15: 45463 | AB15: https://www.nickel28.com/investors/investors-overview/cobalt-27--change-of-auditors?turl=cobalt-27--change-of-auditors#:~:text=Cobalt%2027%20Capital%20Corp.%20is,portfolio%20of%206%20cobalt%20royalties. | AC15: Cobalt 27 Capital Corp. offers pure-play exposure to cobalt for the electric vehicle and battery energy storage markets, involving a diverse portfolio of streams, royalties, and direct investments. | AD15: 28 | AE15: Provider of mineral exploration services based in Toronto, Canada. The company specializes in offering exposure to metals integral to key technologies of the electric vehicle and battery energy storage markets. Has several assets in Canada, but none are operating yet.
A16: 1015 | B16: Commercial | C16: Upstream | D16: Compass Minerals | E16: No | F16: Salt, SOP and Magnesium Chloride Plants | G16: Direct lithium extraction | H16: Lithium | I16: https://www.compassminerals.com/ | J16: 765 N 10500 W | K16: Ogden | L16: UT | M16: US | N16: 84404 | O16: 801-731-3100 | P16: 41.283582 | Q16: -112.22673 | R16: 400 | S16: 11000 | T16: MT contained Li/yr | U16: Compass Minerals | V16: https://www.compassminerals.com/ | W16: Overland Park | X16: KA | Y16: US | Z16: MK | AA16: 45649 | AB16: https://investors.compassminerals.com/investors-relations/investor-news/press-release-details/2022/Compass-Minerals-Announces-Selection-of-Direct-Lithium-Extraction-DLE-Technology-Provider-Attractive-Economics-and-Positive-Sustainability-Profile-for-First-Phase-of-Lithium-Project/default.aspx; https://www.reuters.com/business/autos-transportation/compass-minerals-picks-lithium-extraction-technology-supply-ford-others-2022-09-14/; https://www.compassminerals.com/who-we-are/locations/ | AC16: Compass Minerals is a leading provider of essential minerals and is expanding its portfolio to include lithium extraction. | AD16: 18 | AE16: Compass Minerals is developing a lithium extraction facility to supply Ford and other automakers with lithium carbonate and hydroxide.
